[2024-01-31T16:39:48.523+0000] {taskinstance.py:1956} INFO - Dependencies all met for dep_context=non-requeueable deps ti=<TaskInstance: djinni_etl.extract manual__2024-01-31T16:39:43.812953+00:00 [queued]>
[2024-01-31T16:39:48.534+0000] {taskinstance.py:1956} INFO - Dependencies all met for dep_context=requeueable deps ti=<TaskInstance: djinni_etl.extract manual__2024-01-31T16:39:43.812953+00:00 [queued]>
[2024-01-31T16:39:48.535+0000] {taskinstance.py:2170} INFO - Starting attempt 1 of 1
[2024-01-31T16:39:48.552+0000] {taskinstance.py:2191} INFO - Executing <Task(PythonOperator): extract> on 2024-01-31 16:39:43.812953+00:00
[2024-01-31T16:39:48.559+0000] {standard_task_runner.py:60} INFO - Started process 62 to run task
[2024-01-31T16:39:48.563+0000] {standard_task_runner.py:87} INFO - Running: ['***', 'tasks', 'run', 'djinni_etl', 'extract', 'manual__2024-01-31T16:39:43.812953+00:00', '--job-id', '17', '--raw', '--subdir', 'DAGS_FOLDER/djinni_etl_dag.py', '--cfg-path', '/tmp/tmpl6jh1_4z']
[2024-01-31T16:39:48.566+0000] {standard_task_runner.py:88} INFO - Job 17: Subtask extract
[2024-01-31T16:39:48.627+0000] {task_command.py:423} INFO - Running <TaskInstance: djinni_etl.extract manual__2024-01-31T16:39:43.812953+00:00 [running]> on host dc8f26973ec6
[2024-01-31T16:39:48.763+0000] {taskinstance.py:2480} INFO - Exporting env vars: AIRFLOW_CTX_DAG_OWNER='***' AIRFLOW_CTX_DAG_ID='djinni_etl' AIRFLOW_CTX_TASK_ID='extract' AIRFLOW_CTX_EXECUTION_DATE='2024-01-31T16:39:43.812953+00:00' AIRFLOW_CTX_TRY_NUMBER='1' AIRFLOW_CTX_DAG_RUN_ID='manual__2024-01-31T16:39:43.812953+00:00'
[2024-01-31T16:39:48.767+0000] {taskinstance.py:2698} ERROR - Task failed with exception
Traceback (most recent call last):
  File "/home/airflow/.local/lib/python3.8/site-packages/airflow/models/taskinstance.py", line 433, in _execute_task
    result = execute_callable(context=context, **execute_callable_kwargs)
  File "/home/airflow/.local/lib/python3.8/site-packages/airflow/operators/python.py", line 199, in execute
    return_value = self.execute_callable()
  File "/home/airflow/.local/lib/python3.8/site-packages/airflow/operators/python.py", line 216, in execute_callable
    return self.python_callable(*self.op_args, **self.op_kwargs)
  File "/opt/airflow/dags/functions/extract.py", line 53, in extract_djinni
    _create_output_file(current_date)
  File "/opt/airflow/dags/functions/extract.py", line 39, in _create_output_file
    with open(f"{OUTPUT_FILE_PATH + '/' + current_date}_raw.csv", "w", encoding="UTF8", newline="") as f:
FileNotFoundError: [Errno 2] No such file or directory: '/data/raw/31-01-2024_raw.csv'
[2024-01-31T16:39:48.780+0000] {taskinstance.py:1138} INFO - Marking task as FAILED. dag_id=djinni_etl, task_id=extract, execution_date=20240131T163943, start_date=20240131T163948, end_date=20240131T163948
[2024-01-31T16:39:48.799+0000] {standard_task_runner.py:107} ERROR - Failed to execute job 17 for task extract ([Errno 2] No such file or directory: '/data/raw/31-01-2024_raw.csv'; 62)
[2024-01-31T16:39:48.815+0000] {local_task_job_runner.py:234} INFO - Task exited with return code 1
[2024-01-31T16:39:48.855+0000] {taskinstance.py:3280} INFO - 0 downstream tasks scheduled from follow-on schedule check
