[2024-01-31T17:09:03.793+0000] {taskinstance.py:1956} INFO - Dependencies all met for dep_context=non-requeueable deps ti=<TaskInstance: djinni_etl.extract manual__2024-01-31T17:09:01.472228+00:00 [queued]>
[2024-01-31T17:09:03.803+0000] {taskinstance.py:1956} INFO - Dependencies all met for dep_context=requeueable deps ti=<TaskInstance: djinni_etl.extract manual__2024-01-31T17:09:01.472228+00:00 [queued]>
[2024-01-31T17:09:03.804+0000] {taskinstance.py:2170} INFO - Starting attempt 1 of 1
[2024-01-31T17:09:03.822+0000] {taskinstance.py:2191} INFO - Executing <Task(PythonOperator): extract> on 2024-01-31 17:09:01.472228+00:00
[2024-01-31T17:09:03.836+0000] {standard_task_runner.py:60} INFO - Started process 83 to run task
[2024-01-31T17:09:03.840+0000] {standard_task_runner.py:87} INFO - Running: ['***', 'tasks', 'run', 'djinni_etl', 'extract', 'manual__2024-01-31T17:09:01.472228+00:00', '--job-id', '26', '--raw', '--subdir', 'DAGS_FOLDER/djinni_etl_dag.py', '--cfg-path', '/tmp/tmp0xl4z9kw']
[2024-01-31T17:09:03.843+0000] {standard_task_runner.py:88} INFO - Job 26: Subtask extract
[2024-01-31T17:09:03.898+0000] {task_command.py:423} INFO - Running <TaskInstance: djinni_etl.extract manual__2024-01-31T17:09:01.472228+00:00 [running]> on host 57d9204a78e0
[2024-01-31T17:09:03.987+0000] {taskinstance.py:2480} INFO - Exporting env vars: AIRFLOW_CTX_DAG_OWNER='***' AIRFLOW_CTX_DAG_ID='djinni_etl' AIRFLOW_CTX_TASK_ID='extract' AIRFLOW_CTX_EXECUTION_DATE='2024-01-31T17:09:01.472228+00:00' AIRFLOW_CTX_TRY_NUMBER='1' AIRFLOW_CTX_DAG_RUN_ID='manual__2024-01-31T17:09:01.472228+00:00'
[2024-01-31T17:09:03.988+0000] {taskinstance.py:2698} ERROR - Task failed with exception
Traceback (most recent call last):
  File "/home/airflow/.local/lib/python3.8/site-packages/airflow/models/taskinstance.py", line 433, in _execute_task
    result = execute_callable(context=context, **execute_callable_kwargs)
  File "/home/airflow/.local/lib/python3.8/site-packages/airflow/operators/python.py", line 199, in execute
    return_value = self.execute_callable()
  File "/home/airflow/.local/lib/python3.8/site-packages/airflow/operators/python.py", line 216, in execute_callable
    return self.python_callable(*self.op_args, **self.op_kwargs)
  File "/opt/airflow/dags/djinni_etl_dag.py", line 10, in foo
    with open("/data/raw/test.csv", "w", encoding="UTF8") as f:
FileNotFoundError: [Errno 2] No such file or directory: '/data/raw/test.csv'
[2024-01-31T17:09:03.998+0000] {taskinstance.py:1138} INFO - Marking task as FAILED. dag_id=djinni_etl, task_id=extract, execution_date=20240131T170901, start_date=20240131T170903, end_date=20240131T170903
[2024-01-31T17:09:04.010+0000] {standard_task_runner.py:107} ERROR - Failed to execute job 26 for task extract ([Errno 2] No such file or directory: '/data/raw/test.csv'; 83)
[2024-01-31T17:09:04.052+0000] {local_task_job_runner.py:234} INFO - Task exited with return code 1
[2024-01-31T17:09:04.111+0000] {taskinstance.py:3280} INFO - 0 downstream tasks scheduled from follow-on schedule check
