[2024-01-31T17:19:20.314+0000] {taskinstance.py:1956} INFO - Dependencies all met for dep_context=non-requeueable deps ti=<TaskInstance: djinni_etl.extract manual__2024-01-31T17:19:16.387577+00:00 [queued]>
[2024-01-31T17:19:20.323+0000] {taskinstance.py:1956} INFO - Dependencies all met for dep_context=requeueable deps ti=<TaskInstance: djinni_etl.extract manual__2024-01-31T17:19:16.387577+00:00 [queued]>
[2024-01-31T17:19:20.323+0000] {taskinstance.py:2170} INFO - Starting attempt 1 of 1
[2024-01-31T17:19:20.335+0000] {taskinstance.py:2191} INFO - Executing <Task(PythonOperator): extract> on 2024-01-31 17:19:16.387577+00:00
[2024-01-31T17:19:20.341+0000] {standard_task_runner.py:60} INFO - Started process 69 to run task
[2024-01-31T17:19:20.345+0000] {standard_task_runner.py:87} INFO - Running: ['***', 'tasks', 'run', 'djinni_etl', 'extract', 'manual__2024-01-31T17:19:16.387577+00:00', '--job-id', '32', '--raw', '--subdir', 'DAGS_FOLDER/djinni_etl_dag.py', '--cfg-path', '/tmp/tmpqgh68b_4']
[2024-01-31T17:19:20.348+0000] {standard_task_runner.py:88} INFO - Job 32: Subtask extract
[2024-01-31T17:19:20.395+0000] {task_command.py:423} INFO - Running <TaskInstance: djinni_etl.extract manual__2024-01-31T17:19:16.387577+00:00 [running]> on host 68bbef972a8a
[2024-01-31T17:19:20.478+0000] {taskinstance.py:2480} INFO - Exporting env vars: AIRFLOW_CTX_DAG_OWNER='***' AIRFLOW_CTX_DAG_ID='djinni_etl' AIRFLOW_CTX_TASK_ID='extract' AIRFLOW_CTX_EXECUTION_DATE='2024-01-31T17:19:16.387577+00:00' AIRFLOW_CTX_TRY_NUMBER='1' AIRFLOW_CTX_DAG_RUN_ID='manual__2024-01-31T17:19:16.387577+00:00'
[2024-01-31T17:19:20.481+0000] {taskinstance.py:2698} ERROR - Task failed with exception
Traceback (most recent call last):
  File "/home/airflow/.local/lib/python3.8/site-packages/airflow/models/taskinstance.py", line 433, in _execute_task
    result = execute_callable(context=context, **execute_callable_kwargs)
  File "/home/airflow/.local/lib/python3.8/site-packages/airflow/operators/python.py", line 199, in execute
    return_value = self.execute_callable()
  File "/home/airflow/.local/lib/python3.8/site-packages/airflow/operators/python.py", line 216, in execute_callable
    return self.python_callable(*self.op_args, **self.op_kwargs)
  File "/opt/airflow/dags/functions/extract.py", line 53, in extract_djinni
    _create_output_file(current_date)
  File "/opt/airflow/dags/functions/extract.py", line 39, in _create_output_file
    with open(f"{OUTPUT_FILE_PATH + '/' + current_date}_raw.csv", "w", encoding="UTF8", newline="") as f:
PermissionError: [Errno 13] Permission denied: 'data/raw/31-01-2024_raw.csv'
[2024-01-31T17:19:20.489+0000] {taskinstance.py:1138} INFO - Marking task as FAILED. dag_id=djinni_etl, task_id=extract, execution_date=20240131T171916, start_date=20240131T171920, end_date=20240131T171920
[2024-01-31T17:19:20.501+0000] {standard_task_runner.py:107} ERROR - Failed to execute job 32 for task extract ([Errno 13] Permission denied: 'data/raw/31-01-2024_raw.csv'; 69)
[2024-01-31T17:19:20.517+0000] {local_task_job_runner.py:234} INFO - Task exited with return code 1
[2024-01-31T17:19:20.537+0000] {taskinstance.py:3280} INFO - 0 downstream tasks scheduled from follow-on schedule check
