[2024-02-06T15:25:25.531+0000] {taskinstance.py:1956} INFO - Dependencies all met for dep_context=non-requeueable deps ti=<TaskInstance: djinni_etl.clean_text scheduled__2024-02-06T14:00:00+00:00 [queued]>
[2024-02-06T15:25:25.542+0000] {taskinstance.py:1956} INFO - Dependencies all met for dep_context=requeueable deps ti=<TaskInstance: djinni_etl.clean_text scheduled__2024-02-06T14:00:00+00:00 [queued]>
[2024-02-06T15:25:25.542+0000] {taskinstance.py:2170} INFO - Starting attempt 1 of 1
[2024-02-06T15:25:25.560+0000] {taskinstance.py:2191} INFO - Executing <Task(PythonOperator): clean_text> on 2024-02-06 14:00:00+00:00
[2024-02-06T15:25:25.569+0000] {standard_task_runner.py:60} INFO - Started process 73 to run task
[2024-02-06T15:25:25.572+0000] {standard_task_runner.py:87} INFO - Running: ['***', 'tasks', 'run', 'djinni_etl', 'clean_text', 'scheduled__2024-02-06T14:00:00+00:00', '--job-id', '49', '--raw', '--subdir', 'DAGS_FOLDER/djinni_etl_dag.py', '--cfg-path', '/tmp/tmpzd01il3w']
[2024-02-06T15:25:25.573+0000] {standard_task_runner.py:88} INFO - Job 49: Subtask clean_text
[2024-02-06T15:25:25.626+0000] {task_command.py:423} INFO - Running <TaskInstance: djinni_etl.clean_text scheduled__2024-02-06T14:00:00+00:00 [running]> on host 083162c1f5db
[2024-02-06T15:25:25.716+0000] {taskinstance.py:2480} INFO - Exporting env vars: AIRFLOW_CTX_DAG_OWNER='***' AIRFLOW_CTX_DAG_ID='djinni_etl' AIRFLOW_CTX_TASK_ID='clean_text' AIRFLOW_CTX_EXECUTION_DATE='2024-02-06T14:00:00+00:00' AIRFLOW_CTX_TRY_NUMBER='1' AIRFLOW_CTX_DAG_RUN_ID='scheduled__2024-02-06T14:00:00+00:00'
[2024-02-06T15:25:25.720+0000] {taskinstance.py:2698} ERROR - Task failed with exception
Traceback (most recent call last):
  File "/home/airflow/.local/lib/python3.8/site-packages/airflow/models/taskinstance.py", line 433, in _execute_task
    result = execute_callable(context=context, **execute_callable_kwargs)
  File "/home/airflow/.local/lib/python3.8/site-packages/airflow/operators/python.py", line 199, in execute
    return_value = self.execute_callable()
  File "/home/airflow/.local/lib/python3.8/site-packages/airflow/operators/python.py", line 216, in execute_callable
    return self.python_callable(*self.op_args, **self.op_kwargs)
  File "/opt/airflow/dags/functions/transform.py", line 35, in clean_text
    df = pd.read_csv(f"{RAW_DATA_CSV}/{current_date}_raw.csv")
  File "/home/airflow/.local/lib/python3.8/site-packages/pandas/io/parsers/readers.py", line 912, in read_csv
    return _read(filepath_or_buffer, kwds)
  File "/home/airflow/.local/lib/python3.8/site-packages/pandas/io/parsers/readers.py", line 577, in _read
    parser = TextFileReader(filepath_or_buffer, **kwds)
  File "/home/airflow/.local/lib/python3.8/site-packages/pandas/io/parsers/readers.py", line 1407, in __init__
    self._engine = self._make_engine(f, self.engine)
  File "/home/airflow/.local/lib/python3.8/site-packages/pandas/io/parsers/readers.py", line 1661, in _make_engine
    self.handles = get_handle(
  File "/home/airflow/.local/lib/python3.8/site-packages/pandas/io/common.py", line 859, in get_handle
    handle = open(
FileNotFoundError: [Errno 2] No such file or directory: '../../data/raw/2024-02-06_raw.csv'
[2024-02-06T15:25:25.730+0000] {taskinstance.py:1138} INFO - Marking task as FAILED. dag_id=djinni_etl, task_id=clean_text, execution_date=20240206T140000, start_date=20240206T152525, end_date=20240206T152525
[2024-02-06T15:25:25.743+0000] {standard_task_runner.py:107} ERROR - Failed to execute job 49 for task clean_text ([Errno 2] No such file or directory: '../../data/raw/2024-02-06_raw.csv'; 73)
[2024-02-06T15:25:25.784+0000] {local_task_job_runner.py:234} INFO - Task exited with return code 1
[2024-02-06T15:25:25.807+0000] {taskinstance.py:3280} INFO - 0 downstream tasks scheduled from follow-on schedule check
