[2024-01-31T17:02:00.542+0000] {taskinstance.py:1956} INFO - Dependencies all met for dep_context=non-requeueable deps ti=<TaskInstance: djinni_etl.extract scheduled__2024-01-31T16:00:00+00:00 [queued]>
[2024-01-31T17:02:00.550+0000] {taskinstance.py:1956} INFO - Dependencies all met for dep_context=requeueable deps ti=<TaskInstance: djinni_etl.extract scheduled__2024-01-31T16:00:00+00:00 [queued]>
[2024-01-31T17:02:00.550+0000] {taskinstance.py:2170} INFO - Starting attempt 1 of 1
[2024-01-31T17:02:00.565+0000] {taskinstance.py:2191} INFO - Executing <Task(PythonOperator): extract> on 2024-01-31 16:00:00+00:00
[2024-01-31T17:02:00.571+0000] {standard_task_runner.py:60} INFO - Started process 61 to run task
[2024-01-31T17:02:00.576+0000] {standard_task_runner.py:87} INFO - Running: ['***', 'tasks', 'run', 'djinni_etl', 'extract', 'scheduled__2024-01-31T16:00:00+00:00', '--job-id', '20', '--raw', '--subdir', 'DAGS_FOLDER/djinni_etl_dag.py', '--cfg-path', '/tmp/tmpweitmoly']
[2024-01-31T17:02:00.579+0000] {standard_task_runner.py:88} INFO - Job 20: Subtask extract
[2024-01-31T17:02:00.638+0000] {task_command.py:423} INFO - Running <TaskInstance: djinni_etl.extract scheduled__2024-01-31T16:00:00+00:00 [running]> on host 072d83db9e19
[2024-01-31T17:02:00.733+0000] {taskinstance.py:2480} INFO - Exporting env vars: AIRFLOW_CTX_DAG_OWNER='***' AIRFLOW_CTX_DAG_ID='djinni_etl' AIRFLOW_CTX_TASK_ID='extract' AIRFLOW_CTX_EXECUTION_DATE='2024-01-31T16:00:00+00:00' AIRFLOW_CTX_TRY_NUMBER='1' AIRFLOW_CTX_DAG_RUN_ID='scheduled__2024-01-31T16:00:00+00:00'
[2024-01-31T17:02:00.736+0000] {taskinstance.py:2698} ERROR - Task failed with exception
Traceback (most recent call last):
  File "/home/airflow/.local/lib/python3.8/site-packages/airflow/models/taskinstance.py", line 433, in _execute_task
    result = execute_callable(context=context, **execute_callable_kwargs)
  File "/home/airflow/.local/lib/python3.8/site-packages/airflow/operators/python.py", line 199, in execute
    return_value = self.execute_callable()
  File "/home/airflow/.local/lib/python3.8/site-packages/airflow/operators/python.py", line 216, in execute_callable
    return self.python_callable(*self.op_args, **self.op_kwargs)
  File "/opt/airflow/dags/functions/extract.py", line 53, in extract_djinni
    _create_output_file(current_date)
  File "/opt/airflow/dags/functions/extract.py", line 39, in _create_output_file
    with open(f"{OUTPUT_FILE_PATH + '/' + current_date}_raw.csv", "w", encoding="UTF8", newline="") as f:
FileNotFoundError: [Errno 2] No such file or directory: '../../data/31-01-2024_raw.csv'
[2024-01-31T17:02:00.748+0000] {taskinstance.py:1138} INFO - Marking task as FAILED. dag_id=djinni_etl, task_id=extract, execution_date=20240131T160000, start_date=20240131T170200, end_date=20240131T170200
[2024-01-31T17:02:00.763+0000] {standard_task_runner.py:107} ERROR - Failed to execute job 20 for task extract ([Errno 2] No such file or directory: '../../data/31-01-2024_raw.csv'; 61)
[2024-01-31T17:02:00.788+0000] {local_task_job_runner.py:234} INFO - Task exited with return code 1
[2024-01-31T17:02:00.842+0000] {taskinstance.py:3280} INFO - 0 downstream tasks scheduled from follow-on schedule check
[2024-01-31T17:08:49.969+0000] {taskinstance.py:1956} INFO - Dependencies all met for dep_context=non-requeueable deps ti=<TaskInstance: djinni_etl.extract scheduled__2024-01-31T16:00:00+00:00 [queued]>
[2024-01-31T17:08:49.984+0000] {taskinstance.py:1956} INFO - Dependencies all met for dep_context=requeueable deps ti=<TaskInstance: djinni_etl.extract scheduled__2024-01-31T16:00:00+00:00 [queued]>
[2024-01-31T17:08:49.985+0000] {taskinstance.py:2170} INFO - Starting attempt 1 of 1
[2024-01-31T17:08:50.010+0000] {taskinstance.py:2191} INFO - Executing <Task(PythonOperator): extract> on 2024-01-31 16:00:00+00:00
[2024-01-31T17:08:50.022+0000] {standard_task_runner.py:60} INFO - Started process 79 to run task
[2024-01-31T17:08:50.026+0000] {standard_task_runner.py:87} INFO - Running: ['***', 'tasks', 'run', 'djinni_etl', 'extract', 'scheduled__2024-01-31T16:00:00+00:00', '--job-id', '24', '--raw', '--subdir', 'DAGS_FOLDER/djinni_etl_dag.py', '--cfg-path', '/tmp/tmpfdqrbm4j']
[2024-01-31T17:08:50.030+0000] {standard_task_runner.py:88} INFO - Job 24: Subtask extract
[2024-01-31T17:08:50.111+0000] {task_command.py:423} INFO - Running <TaskInstance: djinni_etl.extract scheduled__2024-01-31T16:00:00+00:00 [running]> on host 57d9204a78e0
[2024-01-31T17:08:50.271+0000] {taskinstance.py:2480} INFO - Exporting env vars: AIRFLOW_CTX_DAG_OWNER='***' AIRFLOW_CTX_DAG_ID='djinni_etl' AIRFLOW_CTX_TASK_ID='extract' AIRFLOW_CTX_EXECUTION_DATE='2024-01-31T16:00:00+00:00' AIRFLOW_CTX_TRY_NUMBER='1' AIRFLOW_CTX_DAG_RUN_ID='scheduled__2024-01-31T16:00:00+00:00'
[2024-01-31T17:08:50.276+0000] {taskinstance.py:2698} ERROR - Task failed with exception
Traceback (most recent call last):
  File "/home/airflow/.local/lib/python3.8/site-packages/airflow/models/taskinstance.py", line 433, in _execute_task
    result = execute_callable(context=context, **execute_callable_kwargs)
  File "/home/airflow/.local/lib/python3.8/site-packages/airflow/operators/python.py", line 199, in execute
    return_value = self.execute_callable()
  File "/home/airflow/.local/lib/python3.8/site-packages/airflow/operators/python.py", line 216, in execute_callable
    return self.python_callable(*self.op_args, **self.op_kwargs)
  File "/opt/airflow/dags/djinni_etl_dag.py", line 10, in foo
    with open("/data/raw/test.csv", "w", encoding="UTF8") as f:
FileNotFoundError: [Errno 2] No such file or directory: '/data/raw/test.csv'
[2024-01-31T17:08:50.295+0000] {taskinstance.py:1138} INFO - Marking task as FAILED. dag_id=djinni_etl, task_id=extract, execution_date=20240131T160000, start_date=20240131T170849, end_date=20240131T170850
[2024-01-31T17:08:50.319+0000] {standard_task_runner.py:107} ERROR - Failed to execute job 24 for task extract ([Errno 2] No such file or directory: '/data/raw/test.csv'; 79)
[2024-01-31T17:08:50.360+0000] {local_task_job_runner.py:234} INFO - Task exited with return code 1
[2024-01-31T17:08:50.399+0000] {taskinstance.py:3280} INFO - 0 downstream tasks scheduled from follow-on schedule check
[2024-01-31T17:12:32.076+0000] {taskinstance.py:1956} INFO - Dependencies all met for dep_context=non-requeueable deps ti=<TaskInstance: djinni_etl.extract scheduled__2024-01-31T16:00:00+00:00 [queued]>
[2024-01-31T17:12:32.084+0000] {taskinstance.py:1956} INFO - Dependencies all met for dep_context=requeueable deps ti=<TaskInstance: djinni_etl.extract scheduled__2024-01-31T16:00:00+00:00 [queued]>
[2024-01-31T17:12:32.084+0000] {taskinstance.py:2170} INFO - Starting attempt 1 of 1
[2024-01-31T17:12:32.096+0000] {taskinstance.py:2191} INFO - Executing <Task(PythonOperator): extract> on 2024-01-31 16:00:00+00:00
[2024-01-31T17:12:32.102+0000] {standard_task_runner.py:60} INFO - Started process 69 to run task
[2024-01-31T17:12:32.105+0000] {standard_task_runner.py:87} INFO - Running: ['***', 'tasks', 'run', 'djinni_etl', 'extract', 'scheduled__2024-01-31T16:00:00+00:00', '--job-id', '29', '--raw', '--subdir', 'DAGS_FOLDER/djinni_etl_dag.py', '--cfg-path', '/tmp/tmpuacyqm_w']
[2024-01-31T17:12:32.108+0000] {standard_task_runner.py:88} INFO - Job 29: Subtask extract
[2024-01-31T17:12:32.152+0000] {task_command.py:423} INFO - Running <TaskInstance: djinni_etl.extract scheduled__2024-01-31T16:00:00+00:00 [running]> on host 9ae18eebe04d
[2024-01-31T17:12:32.238+0000] {taskinstance.py:2480} INFO - Exporting env vars: AIRFLOW_CTX_DAG_OWNER='***' AIRFLOW_CTX_DAG_ID='djinni_etl' AIRFLOW_CTX_TASK_ID='extract' AIRFLOW_CTX_EXECUTION_DATE='2024-01-31T16:00:00+00:00' AIRFLOW_CTX_TRY_NUMBER='1' AIRFLOW_CTX_DAG_RUN_ID='scheduled__2024-01-31T16:00:00+00:00'
[2024-01-31T17:12:32.239+0000] {logging_mixin.py:188} INFO - /opt/***
[2024-01-31T17:12:32.240+0000] {python.py:201} INFO - Done. Returned value was: None
[2024-01-31T17:12:32.248+0000] {taskinstance.py:1138} INFO - Marking task as SUCCESS. dag_id=djinni_etl, task_id=extract, execution_date=20240131T160000, start_date=20240131T171232, end_date=20240131T171232
[2024-01-31T17:12:32.277+0000] {local_task_job_runner.py:234} INFO - Task exited with return code 0
[2024-01-31T17:12:32.294+0000] {taskinstance.py:3280} INFO - 0 downstream tasks scheduled from follow-on schedule check
[2024-01-31T17:23:10.395+0000] {taskinstance.py:1956} INFO - Dependencies all met for dep_context=non-requeueable deps ti=<TaskInstance: djinni_etl.extract scheduled__2024-01-31T16:00:00+00:00 [queued]>
[2024-01-31T17:23:10.404+0000] {taskinstance.py:1956} INFO - Dependencies all met for dep_context=requeueable deps ti=<TaskInstance: djinni_etl.extract scheduled__2024-01-31T16:00:00+00:00 [queued]>
[2024-01-31T17:23:10.404+0000] {taskinstance.py:2170} INFO - Starting attempt 1 of 1
[2024-01-31T17:23:10.419+0000] {taskinstance.py:2191} INFO - Executing <Task(PythonOperator): extract> on 2024-01-31 16:00:00+00:00
[2024-01-31T17:23:10.426+0000] {standard_task_runner.py:60} INFO - Started process 64 to run task
[2024-01-31T17:23:10.431+0000] {standard_task_runner.py:87} INFO - Running: ['***', 'tasks', 'run', 'djinni_etl', 'extract', 'scheduled__2024-01-31T16:00:00+00:00', '--job-id', '35', '--raw', '--subdir', 'DAGS_FOLDER/djinni_etl_dag.py', '--cfg-path', '/tmp/tmpkf_dncoa']
[2024-01-31T17:23:10.434+0000] {standard_task_runner.py:88} INFO - Job 35: Subtask extract
[2024-01-31T17:23:10.491+0000] {task_command.py:423} INFO - Running <TaskInstance: djinni_etl.extract scheduled__2024-01-31T16:00:00+00:00 [running]> on host 675ddaaa0565
[2024-01-31T17:23:10.577+0000] {taskinstance.py:2480} INFO - Exporting env vars: AIRFLOW_CTX_DAG_OWNER='***' AIRFLOW_CTX_DAG_ID='djinni_etl' AIRFLOW_CTX_TASK_ID='extract' AIRFLOW_CTX_EXECUTION_DATE='2024-01-31T16:00:00+00:00' AIRFLOW_CTX_TRY_NUMBER='1' AIRFLOW_CTX_DAG_RUN_ID='scheduled__2024-01-31T16:00:00+00:00'
[2024-01-31T17:23:10.582+0000] {taskinstance.py:2698} ERROR - Task failed with exception
Traceback (most recent call last):
  File "/home/airflow/.local/lib/python3.8/site-packages/airflow/models/taskinstance.py", line 433, in _execute_task
    result = execute_callable(context=context, **execute_callable_kwargs)
  File "/home/airflow/.local/lib/python3.8/site-packages/airflow/operators/python.py", line 199, in execute
    return_value = self.execute_callable()
  File "/home/airflow/.local/lib/python3.8/site-packages/airflow/operators/python.py", line 216, in execute_callable
    return self.python_callable(*self.op_args, **self.op_kwargs)
  File "/opt/airflow/dags/functions/extract.py", line 55, in extract_djinni
    categories_list = _get_input_categories()
  File "/opt/airflow/dags/functions/extract.py", line 18, in _get_input_categories
    with open(INPUT_FILE_PATH, encoding="utf8") as f:
FileNotFoundError: [Errno 2] No such file or directory: '../../input/categories.txt'
[2024-01-31T17:23:10.590+0000] {taskinstance.py:1138} INFO - Marking task as FAILED. dag_id=djinni_etl, task_id=extract, execution_date=20240131T160000, start_date=20240131T172310, end_date=20240131T172310
[2024-01-31T17:23:10.605+0000] {standard_task_runner.py:107} ERROR - Failed to execute job 35 for task extract ([Errno 2] No such file or directory: '../../input/categories.txt'; 64)
[2024-01-31T17:23:10.642+0000] {local_task_job_runner.py:234} INFO - Task exited with return code 1
[2024-01-31T17:23:10.666+0000] {taskinstance.py:3280} INFO - 0 downstream tasks scheduled from follow-on schedule check
[2024-01-31T17:26:40.437+0000] {taskinstance.py:1956} INFO - Dependencies all met for dep_context=non-requeueable deps ti=<TaskInstance: djinni_etl.extract scheduled__2024-01-31T16:00:00+00:00 [queued]>
[2024-01-31T17:26:40.447+0000] {taskinstance.py:1956} INFO - Dependencies all met for dep_context=requeueable deps ti=<TaskInstance: djinni_etl.extract scheduled__2024-01-31T16:00:00+00:00 [queued]>
[2024-01-31T17:26:40.448+0000] {taskinstance.py:2170} INFO - Starting attempt 1 of 1
[2024-01-31T17:26:40.469+0000] {taskinstance.py:2191} INFO - Executing <Task(PythonOperator): extract> on 2024-01-31 16:00:00+00:00
[2024-01-31T17:26:40.477+0000] {standard_task_runner.py:60} INFO - Started process 71 to run task
[2024-01-31T17:26:40.480+0000] {standard_task_runner.py:87} INFO - Running: ['***', 'tasks', 'run', 'djinni_etl', 'extract', 'scheduled__2024-01-31T16:00:00+00:00', '--job-id', '38', '--raw', '--subdir', 'DAGS_FOLDER/djinni_etl_dag.py', '--cfg-path', '/tmp/tmpkrbucqft']
[2024-01-31T17:26:40.483+0000] {standard_task_runner.py:88} INFO - Job 38: Subtask extract
[2024-01-31T17:26:40.533+0000] {task_command.py:423} INFO - Running <TaskInstance: djinni_etl.extract scheduled__2024-01-31T16:00:00+00:00 [running]> on host 43740a70cb32
[2024-01-31T17:26:40.629+0000] {taskinstance.py:2480} INFO - Exporting env vars: AIRFLOW_CTX_DAG_OWNER='***' AIRFLOW_CTX_DAG_ID='djinni_etl' AIRFLOW_CTX_TASK_ID='extract' AIRFLOW_CTX_EXECUTION_DATE='2024-01-31T16:00:00+00:00' AIRFLOW_CTX_TRY_NUMBER='1' AIRFLOW_CTX_DAG_RUN_ID='scheduled__2024-01-31T16:00:00+00:00'
[2024-01-31T17:26:40.632+0000] {taskinstance.py:2698} ERROR - Task failed with exception
Traceback (most recent call last):
  File "/home/airflow/.local/lib/python3.8/site-packages/airflow/models/taskinstance.py", line 433, in _execute_task
    result = execute_callable(context=context, **execute_callable_kwargs)
  File "/home/airflow/.local/lib/python3.8/site-packages/airflow/operators/python.py", line 199, in execute
    return_value = self.execute_callable()
  File "/home/airflow/.local/lib/python3.8/site-packages/airflow/operators/python.py", line 216, in execute_callable
    return self.python_callable(*self.op_args, **self.op_kwargs)
  File "/opt/airflow/dags/functions/extract.py", line 55, in extract_djinni
    categories_list = _get_input_categories()
  File "/opt/airflow/dags/functions/extract.py", line 18, in _get_input_categories
    with open(INPUT_FILE_PATH, encoding="utf8") as f:
FileNotFoundError: [Errno 2] No such file or directory: 'input/categories.txt'
[2024-01-31T17:26:40.643+0000] {taskinstance.py:1138} INFO - Marking task as FAILED. dag_id=djinni_etl, task_id=extract, execution_date=20240131T160000, start_date=20240131T172640, end_date=20240131T172640
[2024-01-31T17:26:40.661+0000] {standard_task_runner.py:107} ERROR - Failed to execute job 38 for task extract ([Errno 2] No such file or directory: 'input/categories.txt'; 71)
[2024-01-31T17:26:40.693+0000] {local_task_job_runner.py:234} INFO - Task exited with return code 1
[2024-01-31T17:26:40.728+0000] {taskinstance.py:3280} INFO - 0 downstream tasks scheduled from follow-on schedule check
[2024-01-31T17:29:21.344+0000] {taskinstance.py:1956} INFO - Dependencies all met for dep_context=non-requeueable deps ti=<TaskInstance: djinni_etl.extract scheduled__2024-01-31T16:00:00+00:00 [queued]>
[2024-01-31T17:29:21.352+0000] {taskinstance.py:1956} INFO - Dependencies all met for dep_context=requeueable deps ti=<TaskInstance: djinni_etl.extract scheduled__2024-01-31T16:00:00+00:00 [queued]>
[2024-01-31T17:29:21.353+0000] {taskinstance.py:2170} INFO - Starting attempt 1 of 1
[2024-01-31T17:29:21.366+0000] {taskinstance.py:2191} INFO - Executing <Task(PythonOperator): extract> on 2024-01-31 16:00:00+00:00
[2024-01-31T17:29:21.373+0000] {standard_task_runner.py:60} INFO - Started process 63 to run task
[2024-01-31T17:29:21.376+0000] {standard_task_runner.py:87} INFO - Running: ['***', 'tasks', 'run', 'djinni_etl', 'extract', 'scheduled__2024-01-31T16:00:00+00:00', '--job-id', '41', '--raw', '--subdir', 'DAGS_FOLDER/djinni_etl_dag.py', '--cfg-path', '/tmp/tmpyjoh3b4b']
[2024-01-31T17:29:21.381+0000] {standard_task_runner.py:88} INFO - Job 41: Subtask extract
[2024-01-31T17:29:21.435+0000] {task_command.py:423} INFO - Running <TaskInstance: djinni_etl.extract scheduled__2024-01-31T16:00:00+00:00 [running]> on host 39049dd83ae5
[2024-01-31T17:29:21.540+0000] {taskinstance.py:2480} INFO - Exporting env vars: AIRFLOW_CTX_DAG_OWNER='***' AIRFLOW_CTX_DAG_ID='djinni_etl' AIRFLOW_CTX_TASK_ID='extract' AIRFLOW_CTX_EXECUTION_DATE='2024-01-31T16:00:00+00:00' AIRFLOW_CTX_TRY_NUMBER='1' AIRFLOW_CTX_DAG_RUN_ID='scheduled__2024-01-31T16:00:00+00:00'
[2024-01-31T17:30:09.589+0000] {python.py:201} INFO - Done. Returned value was: None
[2024-01-31T17:30:09.601+0000] {taskinstance.py:1138} INFO - Marking task as SUCCESS. dag_id=djinni_etl, task_id=extract, execution_date=20240131T160000, start_date=20240131T172921, end_date=20240131T173009
[2024-01-31T17:30:09.660+0000] {local_task_job_runner.py:234} INFO - Task exited with return code 0
[2024-01-31T17:30:09.679+0000] {taskinstance.py:3280} INFO - 0 downstream tasks scheduled from follow-on schedule check
