[2024-02-07T15:05:38.073+0000] {taskinstance.py:1956} INFO - Dependencies all met for dep_context=non-requeueable deps ti=<TaskInstance: djinni_etl.upload_to_s3 scheduled__2024-02-07T14:00:00+00:00 [queued]>
[2024-02-07T15:05:38.080+0000] {taskinstance.py:1956} INFO - Dependencies all met for dep_context=requeueable deps ti=<TaskInstance: djinni_etl.upload_to_s3 scheduled__2024-02-07T14:00:00+00:00 [queued]>
[2024-02-07T15:05:38.080+0000] {taskinstance.py:2170} INFO - Starting attempt 1 of 1
[2024-02-07T15:05:38.091+0000] {taskinstance.py:2191} INFO - Executing <Task(PythonOperator): upload_to_s3> on 2024-02-07 14:00:00+00:00
[2024-02-07T15:05:38.097+0000] {standard_task_runner.py:60} INFO - Started process 62 to run task
[2024-02-07T15:05:38.100+0000] {standard_task_runner.py:87} INFO - Running: ['***', 'tasks', 'run', 'djinni_etl', 'upload_to_s3', 'scheduled__2024-02-07T14:00:00+00:00', '--job-id', '62', '--raw', '--subdir', 'DAGS_FOLDER/djinni_etl_dag.py', '--cfg-path', '/tmp/tmpyag7564p']
[2024-02-07T15:05:38.101+0000] {standard_task_runner.py:88} INFO - Job 62: Subtask upload_to_s3
[2024-02-07T15:05:38.146+0000] {task_command.py:423} INFO - Running <TaskInstance: djinni_etl.upload_to_s3 scheduled__2024-02-07T14:00:00+00:00 [running]> on host 43982938215e
[2024-02-07T15:05:38.215+0000] {taskinstance.py:2480} INFO - Exporting env vars: AIRFLOW_CTX_DAG_OWNER='***' AIRFLOW_CTX_DAG_ID='djinni_etl' AIRFLOW_CTX_TASK_ID='upload_to_s3' AIRFLOW_CTX_EXECUTION_DATE='2024-02-07T14:00:00+00:00' AIRFLOW_CTX_TRY_NUMBER='1' AIRFLOW_CTX_DAG_RUN_ID='scheduled__2024-02-07T14:00:00+00:00'
[2024-02-07T15:05:38.225+0000] {base.py:83} INFO - Using connection ID 's3_conn' for task execution.
[2024-02-07T15:05:38.225+0000] {connection_wrapper.py:378} INFO - AWS Connection (conn_id='s3_conn', conn_type='aws') credentials retrieved from login and password.
[2024-02-07T15:05:39.846+0000] {taskinstance.py:2698} ERROR - Task failed with exception
Traceback (most recent call last):
  File "/home/airflow/.local/lib/python3.8/site-packages/airflow/models/taskinstance.py", line 433, in _execute_task
    result = execute_callable(context=context, **execute_callable_kwargs)
  File "/home/airflow/.local/lib/python3.8/site-packages/airflow/operators/python.py", line 199, in execute
    return_value = self.execute_callable()
  File "/home/airflow/.local/lib/python3.8/site-packages/airflow/operators/python.py", line 216, in execute_callable
    return self.python_callable(*self.op_args, **self.op_kwargs)
  File "/opt/airflow/dags/djinni_etl_dag.py", line 12, in upload_to_s3
    hook.load_file(filename=filename, key=key, bucket_name=bucket_name)
  File "/home/airflow/.local/lib/python3.8/site-packages/airflow/providers/amazon/aws/hooks/s3.py", line 137, in wrapper
    return func(*bound_args.args, **bound_args.kwargs)
  File "/home/airflow/.local/lib/python3.8/site-packages/airflow/providers/amazon/aws/hooks/s3.py", line 91, in wrapper
    return func(*bound_args.args, **bound_args.kwargs)
  File "/home/airflow/.local/lib/python3.8/site-packages/airflow/providers/amazon/aws/hooks/s3.py", line 1104, in load_file
    client.upload_file(filename, bucket_name, key, ExtraArgs=extra_args, Config=self.transfer_config)
  File "/home/airflow/.local/lib/python3.8/site-packages/boto3/s3/inject.py", line 145, in upload_file
    return transfer.upload_file(
  File "/home/airflow/.local/lib/python3.8/site-packages/boto3/s3/transfer.py", line 371, in upload_file
    future.result()
  File "/home/airflow/.local/lib/python3.8/site-packages/s3transfer/futures.py", line 103, in result
    return self._coordinator.result()
  File "/home/airflow/.local/lib/python3.8/site-packages/s3transfer/futures.py", line 266, in result
    raise self._exception
  File "/home/airflow/.local/lib/python3.8/site-packages/s3transfer/tasks.py", line 269, in _main
    self._submit(transfer_future=transfer_future, **kwargs)
  File "/home/airflow/.local/lib/python3.8/site-packages/s3transfer/upload.py", line 591, in _submit
    upload_input_manager.provide_transfer_size(transfer_future)
  File "/home/airflow/.local/lib/python3.8/site-packages/s3transfer/upload.py", line 244, in provide_transfer_size
    self._osutil.get_file_size(transfer_future.meta.call_args.fileobj)
  File "/home/airflow/.local/lib/python3.8/site-packages/s3transfer/utils.py", line 251, in get_file_size
    return os.path.getsize(filename)
  File "/usr/local/lib/python3.8/genericpath.py", line 50, in getsize
    return os.stat(filename).st_size
FileNotFoundError: [Errno 2] No such file or directory: '/data/processed/2024-02-06_processed.csv'
[2024-02-07T15:05:39.859+0000] {taskinstance.py:1138} INFO - Marking task as FAILED. dag_id=djinni_etl, task_id=upload_to_s3, execution_date=20240207T140000, start_date=20240207T150538, end_date=20240207T150539
[2024-02-07T15:05:39.874+0000] {standard_task_runner.py:107} ERROR - Failed to execute job 62 for task upload_to_s3 ([Errno 2] No such file or directory: '/data/processed/2024-02-06_processed.csv'; 62)
[2024-02-07T15:05:39.916+0000] {local_task_job_runner.py:234} INFO - Task exited with return code 1
[2024-02-07T15:05:39.937+0000] {taskinstance.py:3280} INFO - 0 downstream tasks scheduled from follow-on schedule check
[2024-02-07T15:57:49.488+0000] {taskinstance.py:1956} INFO - Dependencies all met for dep_context=non-requeueable deps ti=<TaskInstance: djinni_etl.upload_to_s3 scheduled__2024-02-07T14:00:00+00:00 [queued]>
[2024-02-07T15:57:49.497+0000] {taskinstance.py:1956} INFO - Dependencies all met for dep_context=requeueable deps ti=<TaskInstance: djinni_etl.upload_to_s3 scheduled__2024-02-07T14:00:00+00:00 [queued]>
[2024-02-07T15:57:49.497+0000] {taskinstance.py:2170} INFO - Starting attempt 1 of 1
[2024-02-07T15:57:49.517+0000] {taskinstance.py:2191} INFO - Executing <Task(PythonOperator): upload_to_s3> on 2024-02-07 14:00:00+00:00
[2024-02-07T15:57:49.527+0000] {standard_task_runner.py:60} INFO - Started process 62 to run task
[2024-02-07T15:57:49.532+0000] {standard_task_runner.py:87} INFO - Running: ['***', 'tasks', 'run', 'djinni_etl', 'upload_to_s3', 'scheduled__2024-02-07T14:00:00+00:00', '--job-id', '68', '--raw', '--subdir', 'DAGS_FOLDER/djinni_etl_dag.py', '--cfg-path', '/tmp/tmpcsri6x51']
[2024-02-07T15:57:49.535+0000] {standard_task_runner.py:88} INFO - Job 68: Subtask upload_to_s3
[2024-02-07T15:57:49.594+0000] {task_command.py:423} INFO - Running <TaskInstance: djinni_etl.upload_to_s3 scheduled__2024-02-07T14:00:00+00:00 [running]> on host 6de4bd4bc585
[2024-02-07T15:57:49.693+0000] {taskinstance.py:2480} INFO - Exporting env vars: AIRFLOW_CTX_DAG_OWNER='***' AIRFLOW_CTX_DAG_ID='djinni_etl' AIRFLOW_CTX_TASK_ID='upload_to_s3' AIRFLOW_CTX_EXECUTION_DATE='2024-02-07T14:00:00+00:00' AIRFLOW_CTX_TRY_NUMBER='1' AIRFLOW_CTX_DAG_RUN_ID='scheduled__2024-02-07T14:00:00+00:00'
[2024-02-07T15:57:49.706+0000] {base.py:83} INFO - Using connection ID 's3_conn' for task execution.
[2024-02-07T15:57:49.706+0000] {connection_wrapper.py:378} INFO - AWS Connection (conn_id='s3_conn', conn_type='aws') credentials retrieved from login and password.
[2024-02-07T15:57:51.835+0000] {python.py:201} INFO - Done. Returned value was: None
[2024-02-07T15:57:51.862+0000] {taskinstance.py:1138} INFO - Marking task as SUCCESS. dag_id=djinni_etl, task_id=upload_to_s3, execution_date=20240207T140000, start_date=20240207T155749, end_date=20240207T155751
[2024-02-07T15:57:51.921+0000] {local_task_job_runner.py:234} INFO - Task exited with return code 0
[2024-02-07T15:57:51.942+0000] {taskinstance.py:3280} INFO - 0 downstream tasks scheduled from follow-on schedule check
